<?xml version="1.0"?>
<robot name="mobile_base" xmlns:xacro="http://www.ros.org/wiki/xacro">

    <link name="base_footprint" />

    <link name="base_link">
        <inertial>
            <origin
                xyz="0 0 0"
                rpy="0 0 0" />
            <mass
                value="3.05013833627546" />
            <inertia
                ixx="0.00282873573184269"
                ixy="-1.34642108977171E-07"
                ixz="3.62264183974517E-05"
                iyy="0.00241125343004195"
                iyz="3.17541336190539E-09"
                izz="0.00466072890852247" />
        </inertial>
        <visual>
            <origin
                xyz="0 0 0"
                rpy="0 0 0" />
            <geometry>
                <mesh
                filename="package://krobot_amr_description/meshes/base_link.STL" />
            </geometry>
            <material
                name="">
                <color
                rgba="0.647058823529412 0.619607843137255 0.588235294117647 1" />
            </material>
        </visual>
        <collision>
            <origin
                xyz="0 0 0"
                rpy="0 0 0" />
            <geometry>
                <mesh
                filename="package://krobot_amr_description/meshes/base_link.STL" />
            </geometry>
        </collision>
    </link>
    
    <joint name="base_joint" type="fixed">
        <parent link="base_footprint" />
        <child link="base_link" />
        <origin xyz="0 0 0.085" rpy="0 0 0"/>
    </joint>

    <link
    name="left_wheel">
        <inertial>
            <origin
                xyz="0 0 0"
                rpy="0 0 0" />
            <mass
                value="0.546060060071944" />
            <inertia
                ixx="0.00100429594588788"
                ixy="1.17828555717233E-07"
                ixz="-2.11659705830806E-09"
                iyy="0.00190734224449798"
                iyz="-8.93928077455667E-08"
                izz="0.00100429480035459" />
        </inertial>
        <visual>
            <origin
                xyz="0 0 0"
                rpy="0 0 0" />
            <geometry>
                <mesh
                filename="package://krobot_amr_description/meshes/left_wheel.STL" />
            </geometry>
            <material
                name="">
                <color
                rgba="0.298039215686275 0.298039215686275 0.298039215686275 1" />
            </material>
        </visual>
        <collision>
            <origin
                xyz="0 0 0"
                rpy="0 0 0" />
            <geometry>
                <mesh
                filename="package://krobot_amr_description/meshes/left_wheel.STL" />
            </geometry>
            <surface>
                <friction>
                    <ode>
                        <mu>0.9</mu>
                        <mu2>0.9</mu2>
                    </ode>
                </friction>
            </surface>
        </collision>
    </link>

    <joint
        name="base_left_wheel"
        type="continuous">
        <origin
        xyz="-0.059227 0.12918 -0.012612"
        rpy="0 0 0" />
        <parent
        link="base_link" />
        <child
        link="left_wheel" />
        <axis
        xyz="0 1 0" />
    </joint>

    <link
    name="right_wheel">
        <inertial>
            <origin
                xyz="0 0 0"
                rpy="0 0 0" />
            <mass
                value="0.546060060071944" />
            <inertia
                ixx="0.0010042948817914"
                ixy="-9.16319059622406E-08"
                ixz="-2.13696975270597E-09"
                iyy="0.00190734224449798"
                iyz="1.16095807112114E-07"
                izz="0.00100429586445108" />
        </inertial>
        <visual>
            <origin
                xyz="0 0 0"
                rpy="0 0 0" />
            <geometry>
                <mesh
                filename="package://krobot_amr_description/meshes/right_wheel.STL" />
            </geometry>
            <material
                name="">
                <color
                rgba="0.298039215686275 0.298039215686275 0.298039215686275 1" />
            </material>
        </visual>
        <collision>
            <origin
                xyz="0 0 0"
                rpy="0 0 0" />
            <geometry>
                <mesh
                filename="package://krobot_amr_description/meshes/right_wheel.STL" />
            </geometry>
            <surface>
                <friction>
                    <ode>
                        <mu>0.9</mu>
                        <mu2>0.9</mu2>
                    </ode>
                </friction>
            </surface>
        </collision>
    </link>
    <joint
        name="base_right_wheel"
        type="continuous">
        <origin
        xyz="-0.059232 -0.12918 -0.012617"
        rpy="0 0 0" />
        <parent
        link="base_link" />
        <child
        link="right_wheel" />
        <axis
        xyz="0 1 0" />
    </joint>

    <link
    name="caster">
        <inertial>
            <origin
                xyz="0 0 0"
                rpy="0 0 0" />
            <mass
                value="0.117454061907181" />
            <inertia
                ixx="2.84085593987581E-05"
                ixy="1.35010445332139E-07"
                ixz="6.7322693299636E-06"
                iyy="3.15485424415511E-05"
                iyz="-2.85056167574158E-07"
                izz="3.33738274419381E-05" />
            </inertial>
        <visual>
            <origin
                xyz="0 0 0"
                rpy="0 0 0" />
            <geometry>
                <mesh
                filename="package://krobot_amr_description/meshes/caster.STL" />
            </geometry>
            <material
                name="">
                <color
                rgba="0.647058823529412 0.619607843137255 0.588235294117647 1" />
            </material>
        </visual>
        <collision>
            <origin
                xyz="0 0 0"
                rpy="0 0 0" />
            <geometry>
                <mesh
                filename="package://krobot_amr_description/meshes/caster.STL" />
            </geometry>

        </collision>
    </link>
    <joint
        name="base_caster"
        type="continuous">
        <origin
        xyz="0.1481 -0.00012115 -0.031621"
        rpy="0 0 0" />
        <parent
        link="base_link" />
        <child
        link="caster" />
        <axis
        xyz="0 0 -1" />
    </joint>
    <link
        name="caster_wheel">
        <inertial>
            <origin
                xyz="0 0 0"
                rpy="0 0 0" />
            <mass
                value="0.0267501738812479" />
            <inertia
                ixx="5.65844186423342E-06"
                ixy="-1.44278691817399E-21"
                ixz="-5.62772440327498E-22"
                iyy="9.87141726802175E-06"
                iyz="6.72959251701015E-22"
                izz="5.65844186423342E-06" />
        </inertial>
        <visual>
            <origin
                xyz="0 0 0"
                rpy="0 0 0" />
            <geometry>
                <mesh
                filename="package://krobot_amr_description/meshes/caster_wheel.STL" />
            </geometry>
            <material
                name="">
                <color
                rgba="0 0 0 1" />
            </material>
        </visual>
        <collision>
            <origin
                xyz="0 0 0"
                rpy="0 0 0" />
            <geometry>
                <mesh
                filename="package://krobot_amr_description/meshes/caster_wheel.STL" />
            </geometry>
            <surface>
                <friction>
                    <ode>
                        <mu>0.9</mu>
                        <mu2>0.9</mu2>
                    </ode>
                </friction>
            </surface>
        </collision>
    </link>
    <joint
        name="caster_caster_wheel"
        type="continuous">
        <origin
        xyz="0.020268 -0.00033344 -0.030926"
        rpy="0 0 0" />
        <parent
        link="caster" />
        <child
        link="caster_wheel" />
        <axis
        xyz="0 1 0" />
    </joint>


</robot>